This test file contains tests for the method integer_validator from the 7-base_geometry module.
------------------------------------------------------------------------------------------------
	>>> bg = __import__("7-base_geometry")

	>>> BG = getattr(bg, "BaseGeometry")

	>>> integer_validator = getattr(BG, "integer_validator")

	>>> area = getattr(BG, "area")

	
	>>> a = BG()

	>>> a.area() # doctest: +IGNORE_EXCEPTION_DETAIL
	Traceback (most recent call last):
	Exception

	>>> a.area(2) # doctest: +IGNORE_EXCEPTION_DETAIL
	Traceback (most recent call last):
        TypeError

	>>> c.area() # doctest: +IGNORE_EXCEPTION_DETAIL
	Traceback (most recent call last):
        NameError
	
	>>> a.integer_validator("my_int", 12)

	>>> a.integer_validator("alice", 1.24) # doctest: +ELLIPSIS
	Traceback (most recent call last):
	TypeError: ...

	>>> a.integer_validator("alice", "joy") # doctest: +ELLIPSIS
	Traceback (most recent call last):
        TypeError: ...

	>>> a.integer_validator("alice", [1, 2]) # doctest: +ELLIPSIS
	Traceback (most recent call last):
        TypeError: ...

	>>> a.integer_validator("alice", {1, 2, 3}) # doctest: +ELLIPSIS
	Traceback (most recent call last):
        TypeError: ...

	>>> a.integer_validator("my_val", 0) # doctest: +ELLIPSIS
	Traceback (most recent call last):
        ValueError: ...

	>>> a.integer_validator("my_val", -1) # doctest: +ELLIPSIS
	Traceback (most recent call last):
        ValueError: ...

	>>> b.integer_validator("my_int", 12) # doctest: +ELLIPSIS
	Traceback (most recent call last):
        NameError: ...
	
	>>> a.integer_validator("my_val", -1, 9) # doctest: +IGNORE_EXCEPTION_DETAIL
	Traceback (most recent call last):
        TypeError

	>>> a.integer_validator() # doctest: +IGNORE_EXCEPTION_DETAIL
	Traceback (most recent call last):
        TypeError

	>>> a.integer_validator("my_val") # doctest: +IGNORE_EXCEPTION_DETAIL
	Traceback (most recent call last):
        TypeError

	>>> a.integer_validator("my_val", {'a': 1, 'b': 2}) # doctest: +IGNORE_EXCEPTION_DETAIL
	Traceback (most recent call last):
        TypeError

	>>> a.integer_validator("bool", False) # doctest: +IGNORE_EXCEPTION_DETAIL
	Traceback (most recent call last):
        TypeError

	>>> a.integer_validator("my_tuple", (1, 2))  # doctest: +IGNORE_EXCEPTION_DETAIL
	Traceback (most recent call last):
        TypeError

	>>> a.integer_validator("complex number", 2+5j) # doctest: +IGNORE_EXCEPTION_DETAIL
	Traceback (most recent call last):
        TypeError

	>>> a.integer_validator("frozenset", frozenset(["dandy", "daddy"])) # doctest: +IGNORE_EXCEPTION_DETAIL
	Traceback (most recent call last):
        TypeError

	>>> a.integer_validator("bytes", b"bytes") # doctest: +IGNORE_EXCEPTION_DETAIL
	Traceback (most recent call last):
	TypeError

